Workbook

Sheet Sheet1
A1: ProductID | B1: Title | C1: Photo | D1: BodyRegular | E1: BodyDiscounted | F1: PriceRegular | G1: PriceDiscounted | H1: IsDiscounted | I1: DiscountedUntil | J1: IsPublished | K1: LastModified | L1: Coverage | M1: Product type | N1: Term | O1: Grade level | P1: Package type | Q1: Days | R1: Items | S1: Pieces
A2: GA-QA-HP | B2: Printable Handouts for Grades 7 and 9 | C2: https://res.cloudinary.com/dadubemrv/image/upload/v1771470535/pv600hy73vw3w5yfrdrm.jpg | E2: =CONCATENATE(_xlfn._LONGTEXT("Nabibigatan ka ba sa laptop at projector para sa PowerPoint presentations mo, KasaMath? Tinatamad ka ba, walang time, o nahihirapang gumawa ng PowerPoint? I-download mo na itong ating **FREE printable Math handouts** para: - **Tipid ka sa oras** at ma","kapag-focus ka sa lesson planning mo. - **Maganda at consistent ang formatting** ng figures at mathematical expressions. - **Magaan na ang dala mong gamit** sa classroom dahil wala nang laptop at projector. - **Di na problema ang ipapa-seatwork at a","ctivity** dahil meron na sa handouts. - **Mas focused ang bata** dahil di na sila titingin sa visual aids na nasa board pag nagsusulat. Kung gusto mo namang suportahan ang mission ko na pagbibigay ng FREE Math teaching resources, pwede kang [mag-dona","te](https://texmathpro.github.io/donate/), KasaMath. ## 📥 Download the Handouts"), CHAR(10), CHAR(10), _xlfn.TEXTJOIN(CHAR(10), TRUE, Sheet2!G10:'Sheet2'!J13)," --- Kung gusto mo namang maging updated sa promos, FREEBIES, discounts, at Math-related content, mag-subscribe ka lang sa ating mailing list. Mag-email ka lang ng **SUBSCRIBE** sa [texmathpro@gmail.com](mailto:texmathpro@gmail.com?subject=Subscribe&"&"body=SUBSCRIBE). --- **Happy teaching, KasaMath!** [Jonathan Bacolod](https://texmathpro.github.io/about/) Owner and CEO [TeXMathPro](https://texmathpro.github.io/): Math Teaching Beautified [texmathpro@gmail.com](mailto:texmathpro@gmail.com?subj"&"ect=Subscribe&body=SUBSCRIBE)", "{{< adsense >}}") -> Nabibigatan ka ba sa laptop at projector para sa PowerPoint presentations mo, KasaMath? Tinatamad ka ba, walang time, o nahihirapang gumawa ng PowerPoint? I-download mo na itong ating **FREE printable Math handouts** para: - **Tipid ka sa oras** at makapag-focus ka sa lesson planning mo. - **Maganda at consistent ang formatting** ng figures at mathematical expressions. - **Magaan na ang dala mong gamit** sa classroom dahil wala nang laptop at projector. - **Di na problema ang ipapa-seatwork at activity** dahil meron na sa handouts. - **Mas focused ang bata** dahil di na sila titingin sa visual aids na nasa board pag nagsusulat. Kung gusto mo namang suportahan ang mission ko na pagbibigay ng FREE Math teaching resources, pwede kang [mag-donate](https://texmathpro.github.io/donate/), KasaMath. ## 📥 Download the Handouts - [Grade 7 Handouts for the 1st Term](https://drive.google.com/file/d/150NUP_Nq2tev-Qn00VInZTAaPrUAssmQ/view?usp=drivesdk) - [Grade 9 Handouts for the 1st Term](https://drive.google.com/file/d/1x4fsJFRIZ1vsqPk6OXbzsGErE1XdDNJQ/view?usp=drivesdk) - [Grade 7 Handouts for the 2nd Term](https://drive.google.com/file/d/1-KDJsZditKS4m47wiWkkrUHdmr6OGHRS/view?usp=drivesdk) - [Grade 9 Handouts for the 2nd Term](https://drive.google.com/file/d/1EE_6jJP56HUvwmqvAvF3kXdhOI1EKpPi/view?usp=drivesdk) --- Kung gusto mo namang maging updated sa promos, FREEBIES, discounts, at Math-related content, mag-subscribe ka lang sa ating mailing list. Mag-email ka lang ng **SUBSCRIBE** sa [texmathpro@gmail.com](mailto:texmathpro@gmail.com?subject=Subscribe&body=SUBSCRIBE). --- **Happy teaching, KasaMath!** [Jonathan Bacolod](https://texmathpro.github.io/about/) Owner and CEO [TeXMathPro](https://texmathpro.github.io/): Math Teaching Beautified [texmathpro@gmail.com](mailto:texmathpro@gmail.com?subject=Subscribe&body=SUBSCRIBE){{< adsense >}} | F2: 500 | G2: 0 | H2: TRUE | I2: 46172 | J2: TRUE | K2: 46178
A4: G7-T3-S1-BP | B4: Grade 7 T3 First Summative Test + TOS + Answer Key (Basic) | C4: https://i.imgur.com/DKwxWes.jpeg | D4: =Sheet2!$D$2 -> 0 | E4: =Sheet2!$A$2 -> 0 | F4: 120 | G4: 84 | H4: FALSE | I4: 46176 | J4: FALSE | K4: 46176
A5: G7-T3-S1-SP | B5: Grade 7 T3 First Summative Test + TOS + Answer Key (Standard) | C5: https://i.imgur.com/DKwxWes.jpeg | D5: =Sheet2!$E$2 -> 0 | E5: =Sheet2!$B$2 -> 0 | F5: 165 | G5: 115 | H5: FALSE | I5: 46176 | J5: FALSE | K5: 46176
A6: G7-T3-S1-CP | B6: Grade 7 T3 First Summative Test + TOS + Answer Key (Custom) | C6: https://i.imgur.com/DKwxWes.jpeg | D6: =Sheet2!$F$2 -> 0 | E6: =Sheet2!$C$2 -> 0 | F6: 350 | G6: 245 | H6: FALSE | I6: 46176 | J6: FALSE | K6: 46176
A7: G8-T3-S1-BP | B7: Grade 8 T3 First Summative Test + TOS + Answer Key (Basic) | C7: https://i.imgur.com/taq0wC7.jpeg | D7: =Sheet2!$D$2 -> 0 | E7: =Sheet2!$A$2 -> 0 | F7: 120 | G7: 84 | H7: FALSE | I7: 46176 | J7: FALSE | K7: 46176
A8: G8-T3-S1-SP | B8: Grade 8 T3 First Summative Test + TOS + Answer Key (Standard) | C8: https://i.imgur.com/taq0wC7.jpeg | D8: =Sheet2!$E$2 -> 0 | E8: =Sheet2!$B$2 -> 0 | F8: 165 | G8: 115 | H8: FALSE | I8: 46176 | J8: FALSE | K8: 46176
A9: G8-T3-S1-CP | B9: Grade 8 T3 First Summative Test + TOS + Answer Key (Custom) | C9: https://i.imgur.com/taq0wC7.jpeg | D9: =Sheet2!$F$2 -> 0 | E9: =Sheet2!$C$2 -> 0 | F9: 350 | G9: 245 | H9: FALSE | I9: 46176 | J9: FALSE | K9: 46176
A10: G9-T3-S1-BP | B10: Grade 9 T3 First Summative Test + TOS + Answer Key (Basic) | C10: https://i.imgur.com/GzJQ9w9.jpeg | D10: =Sheet2!$D$2 -> 0 | E10: =Sheet2!$A$2 -> 0 | F10: 120 | G10: 84 | H10: FALSE | I10: 46176 | J10: FALSE | K10: 46176
A11: G9-T3-S1-SP | B11: Grade 9 T3 First Summative Test + TOS + Answer Key (Standard) | C11: https://i.imgur.com/GzJQ9w9.jpeg | D11: =Sheet2!$E$2 -> 0 | E11: =Sheet2!$B$2 -> 0 | F11: 165 | G11: 115 | H11: FALSE | I11: 46176 | J11: FALSE | K11: 46176
A12: G9-T3-S1-CP | B12: Grade 9 T3 First Summative Test + TOS + Answer Key (Custom) | C12: https://i.imgur.com/GzJQ9w9.jpeg | D12: =Sheet2!$F$2 -> 0 | E12: =Sheet2!$C$2 -> 0 | F12: 350 | G12: 245 | H12: FALSE | I12: 46176 | J12: FALSE | K12: 46176
A13: G10-T3-S1-BP | B13: Grade 10 T3 First Summative Test + TOS + Answer Key (Basic) | C13: https://i.imgur.com/IXUG78E.jpeg | D13: =Sheet2!$D$2 -> 0 | E13: =Sheet2!$A$2 -> 0 | F13: 120 | G13: 84 | H13: FALSE | I13: 46176 | J13: FALSE | K13: 46176
A14: G10-T3-S1-SP | B14: Grade 10 T3 First Summative Test + TOS + Answer Key (Standard) | C14: https://i.imgur.com/IXUG78E.jpeg | D14: =Sheet2!$E$2 -> 0 | E14: =Sheet2!$B$2 -> 0 | F14: 165 | G14: 115 | H14: FALSE | I14: 46176 | J14: FALSE | K14: 46176
A15: G10-T3-S1-CP | B15: Grade 10 T3 First Summative Test + TOS + Answer Key (Custom) | C15: https://i.imgur.com/IXUG78E.jpeg | D15: =Sheet2!$F$2 -> 0 | E15: =Sheet2!$C$2 -> 0 | F15: 350 | G15: 245 | H15: FALSE | I15: 46176 | J15: FALSE | K15: 46176
A16: G7-T3-TE-BP | B16: Grade 7 T3 Term Exam + TOS + Answer Key (Basic) | C16: https://i.imgur.com/TYIT3or.jpeg | D16: =Sheet2!$D$2 -> 0 | E16: =Sheet2!$A$2 -> 0 | F16: 120 | G16: 84 | H16: FALSE | I16: 46176 | J16: FALSE | K16: 46176
A17: G7-T3-TE-SP | B17: Grade 7 T3 Term Exam + TOS + Answer Key (Standard) | C17: https://i.imgur.com/TYIT3or.jpeg | D17: =Sheet2!$E$2 -> 0 | E17: =Sheet2!$B$2 -> 0 | F17: 165 | G17: 115 | H17: FALSE | I17: 46176 | J17: FALSE | K17: 46176
A18: G7-T3-TE-CP | B18: Grade 7 T3 Term Exam + TOS + Answer Key (Custom) | C18: https://i.imgur.com/TYIT3or.jpeg | D18: =Sheet2!$F$2 -> 0 | E18: =Sheet2!$C$2 -> 0 | F18: 350 | G18: 245 | H18: FALSE | I18: 46176 | J18: FALSE | K18: 46176
A19: G8-T3-TE-BP | B19: Grade 8 T3 Term Exam + TOS + Answer Key (Basic) | C19: https://i.imgur.com/CTCvbDz.jpeg | D19: =Sheet2!$D$2 -> 0 | E19: =Sheet2!$A$2 -> 0 | F19: 120 | G19: 84 | H19: FALSE | I19: 46176 | J19: FALSE | K19: 46176
A20: G8-T3-TE-SP | B20: Grade 8 T3 Term Exam + TOS + Answer Key (Standard) | C20: https://i.imgur.com/CTCvbDz.jpeg | D20: =Sheet2!$E$2 -> 0 | E20: =Sheet2!$B$2 -> 0 | F20: 165 | G20: 115 | H20: FALSE | I20: 46176 | J20: FALSE | K20: 46176
A21: G8-T3-TE-CP | B21: Grade 8 T3 Term Exam + TOS + Answer Key (Custom) | C21: https://i.imgur.com/CTCvbDz.jpeg | D21: =Sheet2!$F$2 -> 0 | E21: =Sheet2!$C$2 -> 0 | F21: 350 | G21: 245 | H21: FALSE | I21: 46176 | J21: FALSE | K21: 46176
A22: G9-T3-TE-BP | B22: Grade 9 T3 Term Exam + TOS + Answer Key (Basic) | C22: https://i.imgur.com/c0IwjHZ.jpeg | D22: =Sheet2!$D$2 -> 0 | E22: =Sheet2!$A$2 -> 0 | F22: 120 | G22: 84 | H22: FALSE | I22: 46176 | J22: FALSE | K22: 46176
A23: G9-T3-TE-SP | B23: Grade 9 T3 Term Exam + TOS + Answer Key (Standard) | C23: https://i.imgur.com/c0IwjHZ.jpeg | D23: =Sheet2!$E$2 -> 0 | E23: =Sheet2!$B$2 -> 0 | F23: 165 | G23: 115 | H23: FALSE | I23: 46176 | J23: FALSE | K23: 46176
A24: G9-T3-TE-CP | B24: Grade 9 T3 Term Exam + TOS + Answer Key (Custom) | C24: https://i.imgur.com/c0IwjHZ.jpeg | D24: =Sheet2!$F$2 -> 0 | E24: =Sheet2!$C$2 -> 0 | F24: 350 | G24: 245 | H24: FALSE | I24: 46176 | J24: FALSE | K24: 46176
A25: G10-T3-TE-BP | B25: Grade 10 T3 Term Exam + TOS + Answer Key (Basic) | C25: https://i.imgur.com/PsPVTBV.jpeg | D25: =Sheet2!$D$2 -> 0 | E25: =Sheet2!$A$2 -> 0 | F25: 120 | G25: 84 | H25: FALSE | I25: 46176 | J25: FALSE | K25: 46176
A26: G10-T3-TE-SP | B26: Grade 10 T3 Term Exam + TOS + Answer Key (Standard) | C26: https://i.imgur.com/PsPVTBV.jpeg | D26: =Sheet2!$E$2 -> 0 | E26: =Sheet2!$B$2 -> 0 | F26: 165 | G26: 115 | H26: FALSE | I26: 46176 | J26: FALSE | K26: 46176
A27: G10-T3-TE-CP | B27: Grade 10 T3 Term Exam + TOS + Answer Key (Custom) | C27: https://i.imgur.com/PsPVTBV.jpeg | D27: =Sheet2!$F$2 -> 0 | E27: =Sheet2!$C$2 -> 0 | F27: 350 | G27: 245 | H27: FALSE | I27: 46176 | J27: FALSE | K27: 46176
A29: G7-T1-S1-BP | B29: Grade 7 T1 First Summative Test + Answer Key (Basic) | C29: https://res.cloudinary.com/dadubemrv/image/upload/v1783262649/xa3ma5xtgdbpiti2pulm.png, https://res.cloudinary.com/dadubemrv/image/upload/v1783262653/xelrwfv3qo9fte8tcav5.png, https://res.cloudinary.com/dadubemrv/image/upload/v1783262656/erime3c8h1ngvdbdrwdu.png, https://res.cloudinary.com/dadubemrv/image/upload/v1783262658/s6wrnagjw7rwy2jvrk9h.png | D29: =CONCATENATE("*Tinatamad ka ba, walang time, o nahihirapang gumawa ng TOS at ", Sheet1!M29, " mo, ",Sheet1!O29," KasaMath? Kuha ka na ng ", Sheet1!P29,"!* **Bakit perfect para sa’yo ang ", Sheet1!P29,"?** ",Sheet2!D$17, Sheet1!Q29," days - ", Sheet1!R29,"-item Multiple Choice test with Answer Key - Para sa teachers na nagmamadali at hindi kailangan ang TOS", L29, " --- ## Step 1: I-fill out at i-submit ang Order Form. ", "{{< iframe src=""", "https://cityofsmiles.github.io/auto-order-form/?id=", LOWER(A29), """ height=""850"" >}}"," ## Step 2: Payment and Delivery ### Payment Methods Mag-send ka lang ng ₱",Sheet1!F29," para sa **", Sheet1!M29,_xlfn._LONGTEXT("**. - **Landbank**: 0695077289 (Jonathan R. Bacolod) - **GCash**: 09128389571 (Jonathan Bacolod) - **Maya**: 09128389571 (Jonathan Bacolod) **Isend ang Screenshot ng Payment kahit saan dito:** - Email: [texmathpro@gmail.com](mailto:texmathpro@gm","ail.com) - Facebook: https://m.me/jonathan.r.bacolod - Telegram: https://t.me/Jonathan_Bacolod Isesend ko ang files sa email address mo after ng payment. ### Delivery Includes: - **Test** - Test type: "), Sheet1!R29,"-item multiple choice test - Dimensions: A4 bond paper - Format: PDF, created using LaTeX - **Answer Key** - Format: PDF, created using LaTeX", Sheet2!$D$6) -> *Tinatamad ka ba, walang time, o nahihirapang gumawa ng TOS at First Summative test mo, Grade 7 KasaMath? Kuha ka na ng Basic Assessment Package!* **Bakit perfect para sa’yo ang Basic Assessment Package?** - Makakatipid ka sa oras kaya makakapaghabol pa ng lessons. - Maganda at consistent ang formatting ng test questions at figures. - Ready na ang answer key kaya mas madali at mabilis ang pagche-check. - Ready-to-print exam: sakto sa Budget of Work ang covered topics - Number of days: 15 days - 25-item Multiple Choice test with Answer Key - Para sa teachers na nagmamadali at hindi kailangan ang TOS --- 📑 **Competencies Covered** - Draw and describe regular and irregular polygons with 5, 6, 8, or 10 sides, based on measurements of sides and angles, using a ruler and protractor. - Draw triangles, quadrilaterals, and regular polygons (5, 6, 8, or 10 sides) with given angle measures. - Describe and explain the relationships between angle pairs based on their measures. - Classify polygons according to the number of sides, whether they are regular or irregular. - Classify polygons whether they are convex or non-convex. - Deduce the relationship between the exterior angle and adjacent interior angle of a polygon. --- ## Step 1: I-fill out at i-submit ang Order Form. {{< iframe src="https://cityofsmiles.github.io/auto-order-form/?id=g7-t1-s1-bp" height="850" >}} ## Step 2: Payment and Delivery ### Payment Methods Mag-send ka lang ng ₱59 para sa **First Summative test**. - **Landbank**: 0695077289 (Jonathan R. Bacolod) - **GCash**: 09128389571 (Jonathan Bacolod) - **Maya**: 09128389571 (Jonathan Bacolod) **Isend ang Screenshot ng Payment kahit saan dito:** - Email: [texmathpro@gmail.com](mailto:texmathpro@gmail.com) - Facebook: https://m.me/jonathan.r.bacolod - Telegram: https://t.me/Jonathan_Bacolod Isesend ko ang files sa email address mo after ng payment. ### Delivery Includes: - **Test** - Test type: 25-item multiple choice test - Dimensions: A4 bond paper - Format: PDF, created using LaTeX - **Answer Key** - Format: PDF, created using LaTeX --- Salamat sa pagsuporta sa **TeXMathPro, KasaMath**! Kung may tanong o suggestion ka, [kontakin mo lang ako](mailto:texmathpro@gmail.com). | F29: 59 | G29: 49 | H29: FALSE | I29: 46176 | J29: TRUE | K29: 46179 | L29: --- 📑 **Competencies Covered** - Draw and describe regular and irregular polygons with 5, 6, 8, or 10 sides, based on measurements of sides and angles, using a ruler and protractor. - Draw triangles, quadrilaterals, and regular polygons (5, 6, 8, or 10 sides) with given angle measures. - Describe and explain the relationships between angle pairs based on their measures. - Classify polygons according to the number of sides, whether they are regular or irregular. - Classify polygons whether they are convex or non-convex. - Deduce the relationship between the exterior angle and adjacent interior angle of a polygon. | M29: {=_xlfn.XLOOKUP(TRUE,ISNUMBER(SEARCH(Sheet2!A$23:A$26,A29)),Sheet2!B$23:B$26,"")} -> First Summative test | N29: {=_xlfn.XLOOKUP(TRUE,ISNUMBER(SEARCH(Sheet2!A$32:A$34,A29)),Sheet2!B$32:B$34,"")} -> First Term | O29: {=_xlfn.XLOOKUP(TRUE,ISNUMBER(SEARCH(Sheet2!A$38:A$41,A29)),Sheet2!B$38:B$41,"")} -> Grade 7 | P29: {=_xlfn.XLOOKUP(TRUE,ISNUMBER(SEARCH(Sheet2!A$45:A$47,A29)),Sheet2!B$45:B$47,"")} -> Basic Assessment Package | Q29: 15 | R29: 25
A30: G7-T1-S1-SP | B30: Grade 7 T1 First Summative Test + Answer Key + TOS (Standard) | C30: https://res.cloudinary.com/dadubemrv/image/upload/v1783262649/xa3ma5xtgdbpiti2pulm.png, https://res.cloudinary.com/dadubemrv/image/upload/v1783262653/xelrwfv3qo9fte8tcav5.png, https://res.cloudinary.com/dadubemrv/image/upload/v1783262656/erime3c8h1ngvdbdrwdu.png, https://res.cloudinary.com/dadubemrv/image/upload/v1783262658/s6wrnagjw7rwy2jvrk9h.png | D30: =CONCATENATE("*Tinatamad ka ba, walang time, o nahihirapang gumawa ng TOS at ", Sheet1!M30, " mo, ",Sheet1!O30," KasaMath? Kuha ka na ng ", Sheet1!P30,"!* **Bakit perfect para sa’yo ang ", Sheet1!P30,"?** ",Sheet2!E$17, Sheet1!Q30," days - ", Sheet1!R30,"-item Multiple Choice test with Answer Key - Bagay sa teachers na gusto ng kumpletong exam, answer key, at TOS", _xlfn._LONGTEXT(" [![Sample TOS formatted using 21st Century Skills](https://res.cloudinary.com/dadubemrv/image/upload/v1768351176/tv5zwilsnzrad6r2q6sw.png)](https://res.cloudinary.com/dadubemrv/image/upload/v1768351176/tv5zwilsnzrad6r2q6sw.png) *Sample TOS formatted us","ing 21st Century Skills*"),L30, " --- ## Step 1: I-fill out at i-submit ang Order Form. ", "{{< iframe src=""", "https://cityofsmiles.github.io/auto-order-form/?id=", LOWER(A30), """ height=""850"" >}}"," ## Step 2: Payment and Delivery ### Payment Methods Mag-send ka lang ng ₱",Sheet1!F30," para sa **", Sheet1!M30,_xlfn._LONGTEXT("**. - **Landbank**: 0695077289 (Jonathan R. Bacolod) - **GCash**: 09128389571 (Jonathan Bacolod) - **Maya**: 09128389571 (Jonathan Bacolod) **Isend ang Screenshot ng Payment kahit saan dito:** - Email: [texmathpro@gmail.com](mailto:texmathpro@gm","ail.com) - Facebook: https://m.me/jonathan.r.bacolod - Telegram: https://t.me/Jonathan_Bacolod Isesend ko ang files sa email address mo after ng payment. ### Delivery Includes: - **Test** - Test type: "), Sheet1!R30,"-item multiple choice test - Dimensions: A4 bond paper - Format: PDF, created using LaTeX - **Answer Key** - Format: PDF, created using LaTeX - **Table of Specifications** - XLSX format", Sheet2!$D$6) -> *Tinatamad ka ba, walang time, o nahihirapang gumawa ng TOS at First Summative test mo, Grade 7 KasaMath? Kuha ka na ng Standard Assessment Package!* **Bakit perfect para sa’yo ang Standard Assessment Package?** - Makakatipid ka sa oras kaya makakapaghabol pa ng lessons. - Maganda at consistent ang formatting ng test questions at figures. - Ready na ang answer key kaya mas madali at mabilis ang pagche-check. - Ready-to-print exam: sakto sa Budget of Work ang covered topics - Maaga kang makakapag-submit ng TOS sa head mo. - Table of Specifications using the 21st Century format - Number of days: 15 days - 25-item Multiple Choice test with Answer Key - Bagay sa teachers na gusto ng kumpletong exam, answer key, at TOS [![Sample TOS formatted using 21st Century Skills](https://res.cloudinary.com/dadubemrv/image/upload/v1768351176/tv5zwilsnzrad6r2q6sw.png)](https://res.cloudinary.com/dadubemrv/image/upload/v1768351176/tv5zwilsnzrad6r2q6sw.png) *Sample TOS formatted using 21st Century Skills* --- 📑 **Competencies Covered** - Draw and describe regular and irregular polygons with 5, 6, 8, or 10 sides, based on measurements of sides and angles, using a ruler and protractor. - Draw triangles, quadrilaterals, and regular polygons (5, 6, 8, or 10 sides) with given angle measures. - Describe and explain the relationships between angle pairs based on their measures. - Classify polygons according to the number of sides, whether they are regular or irregular. - Classify polygons whether they are convex or non-convex. - Deduce the relationship between the exterior angle and adjacent interior angle of a polygon. --- ## Step 1: I-fill out at i-submit ang Order Form. {{< iframe src="https://cityofsmiles.github.io/auto-order-form/?id=g7-t1-s1-sp" height="850" >}} ## Step 2: Payment and Delivery ### Payment Methods Mag-send ka lang ng ₱79 para sa **First Summative test**. - **Landbank**: 0695077289 (Jonathan R. Bacolod) - **GCash**: 09128389571 (Jonathan Bacolod) - **Maya**: 09128389571 (Jonathan Bacolod) **Isend ang Screenshot ng Payment kahit saan dito:** - Email: [texmathpro@gmail.com](mailto:texmathpro@gmail.com) - Facebook: https://m.me/jonathan.r.bacolod - Telegram: https://t.me/Jonathan_Bacolod Isesend ko ang files sa email address mo after ng payment. ### Delivery Includes: - **Test** - Test type: 25-item multiple choice test - Dimensions: A4 bond paper - Format: PDF, created using LaTeX - **Answer Key** - Format: PDF, created using LaTeX - **Table of Specifications** - XLSX format --- Salamat sa pagsuporta sa **TeXMathPro, KasaMath**! Kung may tanong o suggestion ka, [kontakin mo lang ako](mailto:texmathpro@gmail.com). | F30: 79 | G30: 69 | H30: FALSE | I30: 46176 | J30: TRUE | K30: 46179 | L30: --- 📑 **Competencies Covered** - Draw and describe regular and irregular polygons with 5, 6, 8, or 10 sides, based on measurements of sides and angles, using a ruler and protractor. - Draw triangles, quadrilaterals, and regular polygons (5, 6, 8, or 10 sides) with given angle measures. - Describe and explain the relationships between angle pairs based on their measures. - Classify polygons according to the number of sides, whether they are regular or irregular. - Classify polygons whether they are convex or non-convex. - Deduce the relationship between the exterior angle and adjacent interior angle of a polygon. | M30: {=_xlfn.XLOOKUP(TRUE,ISNUMBER(SEARCH(Sheet2!A$23:A$26,A30)),Sheet2!B$23:B$26,"")} -> First Summative test | N30: {=_xlfn.XLOOKUP(TRUE,ISNUMBER(SEARCH(Sheet2!A$32:A$34,A30)),Sheet2!B$32:B$34,"")} -> First Term | O30: {=_xlfn.XLOOKUP(TRUE,ISNUMBER(SEARCH(Sheet2!A$38:A$41,A30)),Sheet2!B$38:B$41,"")} -> Grade 7 | P30: {=_xlfn.XLOOKUP(TRUE,ISNUMBER(SEARCH(Sheet2!A$45:A$47,A30)),Sheet2!B$45:B$47,"")} -> Standard Assessment Package | Q30: 15 | R30: 25
A31: G7-T1-S1-CP | B31: Grade 7 T1 First Summative Test + Answer Key + TOS (Custom) | C31: https://res.cloudinary.com/dadubemrv/image/upload/v1783262649/xa3ma5xtgdbpiti2pulm.png, https://res.cloudinary.com/dadubemrv/image/upload/v1783262653/xelrwfv3qo9fte8tcav5.png, https://res.cloudinary.com/dadubemrv/image/upload/v1783262656/erime3c8h1ngvdbdrwdu.png, https://res.cloudinary.com/dadubemrv/image/upload/v1783262658/s6wrnagjw7rwy2jvrk9h.png | D31: =CONCATENATE("*Tinatamad ka ba, walang time, o nahihirapang gumawa ng TOS at ", Sheet1!M31, " mo, ",Sheet1!O31," KasaMath? Kuha ka na ng ", Sheet1!P31,"!* **Bakit perfect para sa’yo ang ", Sheet1!P31,"?** ",Sheet2!F$17," - Perfect sa teachers na gusto ng pasadyang exam", _xlfn._LONGTEXT(" [![Sample TOS formatted using 21st Century Skills](https://res.cloudinary.com/dadubemrv/image/upload/v1768351176/tv5zwilsnzrad6r2q6sw.png)](https://res.cloudinary.com/dadubemrv/image/upload/v1768351176/tv5zwilsnzrad6r2q6sw.png) *Sample TOS formatted us","ing 21st Century Skills*"),L31, " --- ## Step 1: I-fill out at i-submit ang Order Form. ", "{{< iframe src=""", "https://cityofsmiles.github.io/auto-order-form/?id=", LOWER(A31), """ height=""850"" >}}"," ## Step 2: Payment and Delivery ### Payment Methods Mag-send ka lang ng ₱",Sheet1!F31," para sa **", Sheet1!M31,_xlfn._LONGTEXT("**. - **Landbank**: 0695077289 (Jonathan R. Bacolod) - **GCash**: 09128389571 (Jonathan Bacolod) - **Maya**: 09128389571 (Jonathan Bacolod) **Isend ang Screenshot ng Payment kahit saan dito:** - Email: [texmathpro@gmail.com](mailto:texmathpro@gm","ail.com) - Facebook: https://m.me/jonathan.r.bacolod - Telegram: https://t.me/Jonathan_Bacolod Isesend ko ang files sa email address mo after ng payment. ### Delivery Includes: - **Test** - Test type: "), Sheet1!R31,"-item multiple choice test - Dimensions: A4 bond paper - Format: PDF, created using LaTeX - **Answer Key** - Format: PDF, created using LaTeX - **Table of Specifications** - XLSX format", Sheet2!$D$6) -> *Tinatamad ka ba, walang time, o nahihirapang gumawa ng TOS at First Summative test mo, Grade 7 KasaMath? Kuha ka na ng Custom Assessment Package!* **Bakit perfect para sa’yo ang Custom Assessment Package?** - Makakatipid ka sa oras kaya makakapaghabol pa ng lessons. - Maganda at consistent ang formatting ng test questions at figures. - Ready na ang answer key kaya mas madali at mabilis ang pagche-check. - Fully customizable exam: kahit anong topic ang pwedeng covered - Maaga kang makakapag-submit ng TOS sa head mo. - Table of Specifications using the 21st Century format - Number of days: pwede kahit ilan - Number of items: kahit ilan basta maximum of 50 - Perfect sa teachers na gusto ng pasadyang exam [![Sample TOS formatted using 21st Century Skills](https://res.cloudinary.com/dadubemrv/image/upload/v1768351176/tv5zwilsnzrad6r2q6sw.png)](https://res.cloudinary.com/dadubemrv/image/upload/v1768351176/tv5zwilsnzrad6r2q6sw.png) *Sample TOS formatted using 21st Century Skills* --- 📑 **Competencies Covered** - Draw and describe regular and irregular polygons with 5, 6, 8, or 10 sides, based on measurements of sides and angles, using a ruler and protractor. - Draw triangles, quadrilaterals, and regular polygons (5, 6, 8, or 10 sides) with given angle measures. - Describe and explain the relationships between angle pairs based on their measures. - Classify polygons according to the number of sides, whether they are regular or irregular. - Classify polygons whether they are convex or non-convex. - Deduce the relationship between the exterior angle and adjacent interior angle of a polygon. --- ## Step 1: I-fill out at i-submit ang Order Form. {{< iframe src="https://cityofsmiles.github.io/auto-order-form/?id=g7-t1-s1-cp" height="850" >}} ## Step 2: Payment and Delivery ### Payment Methods Mag-send ka lang ng ₱179 para sa **First Summative test**. - **Landbank**: 0695077289 (Jonathan R. Bacolod) - **GCash**: 09128389571 (Jonathan Bacolod) - **Maya**: 09128389571 (Jonathan Bacolod) **Isend ang Screenshot ng Payment kahit saan dito:** - Email: [texmathpro@gmail.com](mailto:texmathpro@gmail.com) - Facebook: https://m.me/jonathan.r.bacolod - Telegram: https://t.me/Jonathan_Bacolod Isesend ko ang files sa email address mo after ng payment. ### Delivery Includes: - **Test** - Test type: 25-50-item multiple choice test - Dimensions: A4 bond paper - Format: PDF, created using LaTeX - **Answer Key** - Format: PDF, created using LaTeX - **Table of Specifications** - XLSX format --- Salamat sa pagsuporta sa **TeXMathPro, KasaMath**! Kung may tanong o suggestion ka, [kontakin mo lang ako](mailto:texmathpro@gmail.com). | F31: 179 | G31: 169 | H31: FALSE | I31: 46176 | J31: TRUE | K31: 46179 | L31: --- 📑 **Competencies Covered** - Draw and describe regular and irregular polygons with 5, 6, 8, or 10 sides, based on measurements of sides and angles, using a ruler and protractor. - Draw triangles, quadrilaterals, and regular polygons (5, 6, 8, or 10 sides) with given angle measures. - Describe and explain the relationships between angle pairs based on their measures. - Classify polygons according to the number of sides, whether they are regular or irregular. - Classify polygons whether they are convex or non-convex. - Deduce the relationship between the exterior angle and adjacent interior angle of a polygon. | M31: {=_xlfn.XLOOKUP(TRUE,ISNUMBER(SEARCH(Sheet2!A$23:A$26,A31)),Sheet2!B$23:B$26,"")} -> First Summative test | N31: {=_xlfn.XLOOKUP(TRUE,ISNUMBER(SEARCH(Sheet2!A$32:A$34,A31)),Sheet2!B$32:B$34,"")} -> First Term | O31: {=_xlfn.XLOOKUP(TRUE,ISNUMBER(SEARCH(Sheet2!A$38:A$41,A31)),Sheet2!B$38:B$41,"")} -> Grade 7 | P31: {=_xlfn.XLOOKUP(TRUE,ISNUMBER(SEARCH(Sheet2!A$45:A$47,A31)),Sheet2!B$45:B$47,"")} -> Custom Assessment Package | R31: 25-50
A32: G7-T1-S2-BP | B32: Grade 7 T1 Second Summative Test + Answer Key (Basic) | C32: https://res.cloudinary.com/dadubemrv/image/upload/v1784692768/blzn2f4qf4csagllrdmj.png,https://res.cloudinary.com/dadubemrv/image/upload/v1784692772/mlwmihwoocbpcd5of6rx.png,https://res.cloudinary.com/dadubemrv/image/upload/v1784692776/adpmufdqkz5qxw5yzj0p.png | D32: =CONCATENATE("*Tinatamad ka ba, walang time, o nahihirapang gumawa ng TOS at ", Sheet1!M32, " mo, ",Sheet1!O32," KasaMath? Kuha ka na ng ", Sheet1!P32,"!* **Bakit perfect para sa’yo ang ", Sheet1!P32,"?** ",Sheet2!D$17, Sheet1!Q32," days - ", Sheet1!R32,"-item Multiple Choice test with Answer Key - Para sa teachers na nagmamadali at hindi kailangan ang TOS", L32, " --- ## Step 1: I-fill out at i-submit ang Order Form. ", "{{< iframe src=""", "https://cityofsmiles.github.io/auto-order-form/?id=", LOWER(A32), """ height=""850"" >}}"," ## Step 2: Payment and Delivery ### Payment Methods Mag-send ka lang ng ₱",Sheet1!F32," para sa **", Sheet1!M32,_xlfn._LONGTEXT("**. - **Landbank**: 0695077289 (Jonathan R. Bacolod) - **GCash**: 09128389571 (Jonathan Bacolod) - **Maya**: 09128389571 (Jonathan Bacolod) **Isend ang Screenshot ng Payment kahit saan dito:** - Email: [texmathpro@gmail.com](mailto:texmathpro@gm","ail.com) - Facebook: https://m.me/jonathan.r.bacolod - Telegram: https://t.me/Jonathan_Bacolod Isesend ko ang files sa email address mo after ng payment. ### Delivery Includes: - **Test** - Test type: "), Sheet1!R32,"-item multiple choice test - Dimensions: A4 bond paper - Format: PDF, created using LaTeX - **Answer Key** - Format: PDF, created using LaTeX", Sheet2!$D$6) -> *Tinatamad ka ba, walang time, o nahihirapang gumawa ng TOS at Second Summative test mo, Grade 7 KasaMath? Kuha ka na ng Basic Assessment Package!* **Bakit perfect para sa’yo ang Basic Assessment Package?** - Makakatipid ka sa oras kaya makakapaghabol pa ng lessons. - Maganda at consistent ang formatting ng test questions at figures. - Ready na ang answer key kaya mas madali at mabilis ang pagche-check. - Ready-to-print exam: sakto sa Budget of Work ang covered topics - Number of days: 15 days - 25-item Multiple Choice test with Answer Key - Para sa teachers na nagmamadali at hindi kailangan ang TOS --- 📑 **Competencies Covered** - Determine the measures of angles of polygons. - Determine the number of sides of polygons. - Solve problems involving percentage increase and percentage decrease. - Solve money problems involving percentages (e. g., discount, commission, sales tax, simple interest). - Create a financial plan. --- ## Step 1: I-fill out at i-submit ang Order Form. {{< iframe src="https://cityofsmiles.github.io/auto-order-form/?id=g7-t1-s2-bp" height="850" >}} ## Step 2: Payment and Delivery ### Payment Methods Mag-send ka lang ng ₱59 para sa **Second Summative test**. - **Landbank**: 0695077289 (Jonathan R. Bacolod) - **GCash**: 09128389571 (Jonathan Bacolod) - **Maya**: 09128389571 (Jonathan Bacolod) **Isend ang Screenshot ng Payment kahit saan dito:** - Email: [texmathpro@gmail.com](mailto:texmathpro@gmail.com) - Facebook: https://m.me/jonathan.r.bacolod - Telegram: https://t.me/Jonathan_Bacolod Isesend ko ang files sa email address mo after ng payment. ### Delivery Includes: - **Test** - Test type: 25-item multiple choice test - Dimensions: A4 bond paper - Format: PDF, created using LaTeX - **Answer Key** - Format: PDF, created using LaTeX --- Salamat sa pagsuporta sa **TeXMathPro, KasaMath**! Kung may tanong o suggestion ka, [kontakin mo lang ako](mailto:texmathpro@gmail.com). | F32: 59 | G32: 49 | H32: FALSE | I32: 46176 | J32: TRUE | K32: 46179 | L32: --- 📑 **Competencies Covered** - Determine the measures of angles of polygons. - Determine the number of sides of polygons. - Solve problems involving percentage increase and percentage decrease. - Solve money problems involving percentages (e. g., discount, commission, sales tax, simple interest). - Create a financial plan. | M32: {=_xlfn.XLOOKUP(TRUE,ISNUMBER(SEARCH(Sheet2!A$23:A$26,A32)),Sheet2!B$23:B$26,"")} -> Second Summative test | N32: {=_xlfn.XLOOKUP(TRUE,ISNUMBER(SEARCH(Sheet2!A$32:A$34,A32)),Sheet2!B$32:B$34,"")} -> First Term | O32: {=_xlfn.XLOOKUP(TRUE,ISNUMBER(SEARCH(Sheet2!A$38:A$41,A32)),Sheet2!B$38:B$41,"")} -> Grade 7 | P32: {=_xlfn.XLOOKUP(TRUE,ISNUMBER(SEARCH(Sheet2!A$45:A$47,A32)),Sheet2!B$45:B$47,"")} -> Basic Assessment Package | Q32: 15 | R32: 25
A33: G7-T1-S2-SP | B33: Grade 7 T1 Second Summative Test + Answer Key + TOS (Standard) | C33: https://res.cloudinary.com/dadubemrv/image/upload/v1784692768/blzn2f4qf4csagllrdmj.png,https://res.cloudinary.com/dadubemrv/image/upload/v1784692772/mlwmihwoocbpcd5of6rx.png,https://res.cloudinary.com/dadubemrv/image/upload/v1784692776/adpmufdqkz5qxw5yzj0p.png | D33: =CONCATENATE("*Tinatamad ka ba, walang time, o nahihirapang gumawa ng TOS at ", Sheet1!M33, " mo, ",Sheet1!O33," KasaMath? Kuha ka na ng ", Sheet1!P33,"!* **Bakit perfect para sa’yo ang ", Sheet1!P33,"?** ",Sheet2!E$17, Sheet1!Q33," days - ", Sheet1!R33,"-item Multiple Choice test with Answer Key - Bagay sa teachers na gusto ng kumpletong exam, answer key, at TOS", _xlfn._LONGTEXT(" [![Sample TOS formatted using 21st Century Skills](https://res.cloudinary.com/dadubemrv/image/upload/v1768351176/tv5zwilsnzrad6r2q6sw.png)](https://res.cloudinary.com/dadubemrv/image/upload/v1768351176/tv5zwilsnzrad6r2q6sw.png) *Sample TOS formatted us","ing 21st Century Skills*"),L33, " --- ## Step 1: I-fill out at i-submit ang Order Form. ", "{{< iframe src=""", "https://cityofsmiles.github.io/auto-order-form/?id=", LOWER(A33), """ height=""850"" >}}"," ## Step 2: Payment and Delivery ### Payment Methods Mag-send ka lang ng ₱",Sheet1!F33," para sa **", Sheet1!M33,_xlfn._LONGTEXT("**. - **Landbank**: 0695077289 (Jonathan R. Bacolod) - **GCash**: 09128389571 (Jonathan Bacolod) - **Maya**: 09128389571 (Jonathan Bacolod) **Isend ang Screenshot ng Payment kahit saan dito:** - Email: [texmathpro@gmail.com](mailto:texmathpro@gm","ail.com) - Facebook: https://m.me/jonathan.r.bacolod - Telegram: https://t.me/Jonathan_Bacolod Isesend ko ang files sa email address mo after ng payment. ### Delivery Includes: - **Test** - Test type: "), Sheet1!R33,"-item multiple choice test - Dimensions: A4 bond paper - Format: PDF, created using LaTeX - **Answer Key** - Format: PDF, created using LaTeX - **Table of Specifications** - XLSX format", Sheet2!$D$6) -> *Tinatamad ka ba, walang time, o nahihirapang gumawa ng TOS at Second Summative test mo, Grade 7 KasaMath? Kuha ka na ng Standard Assessment Package!* **Bakit perfect para sa’yo ang Standard Assessment Package?** - Makakatipid ka sa oras kaya makakapaghabol pa ng lessons. - Maganda at consistent ang formatting ng test questions at figures. - Ready na ang answer key kaya mas madali at mabilis ang pagche-check. - Ready-to-print exam: sakto sa Budget of Work ang covered topics - Maaga kang makakapag-submit ng TOS sa head mo. - Table of Specifications using the 21st Century format - Number of days: 15 days - 25-item Multiple Choice test with Answer Key - Bagay sa teachers na gusto ng kumpletong exam, answer key, at TOS [![Sample TOS formatted using 21st Century Skills](https://res.cloudinary.com/dadubemrv/image/upload/v1768351176/tv5zwilsnzrad6r2q6sw.png)](https://res.cloudinary.com/dadubemrv/image/upload/v1768351176/tv5zwilsnzrad6r2q6sw.png) *Sample TOS formatted using 21st Century Skills* --- 📑 **Competencies Covered** - Determine the measures of angles of polygons. - Determine the number of sides of polygons. - Solve problems involving percentage increase and percentage decrease. - Solve money problems involving percentages (e. g., discount, commission, sales tax, simple interest). - Create a financial plan. --- ## Step 1: I-fill out at i-submit ang Order Form. {{< iframe src="https://cityofsmiles.github.io/auto-order-form/?id=g7-t1-s2-sp" height="850" >}} ## Step 2: Payment and Delivery ### Payment Methods Mag-send ka lang ng ₱79 para sa **Second Summative test**. - **Landbank**: 0695077289 (Jonathan R. Bacolod) - **GCash**: 09128389571 (Jonathan Bacolod) - **Maya**: 09128389571 (Jonathan Bacolod) **Isend ang Screenshot ng Payment kahit saan dito:** - Email: [texmathpro@gmail.com](mailto:texmathpro@gmail.com) - Facebook: https://m.me/jonathan.r.bacolod - Telegram: https://t.me/Jonathan_Bacolod Isesend ko ang files sa email address mo after ng payment. ### Delivery Includes: - **Test** - Test type: 25-item multiple choice test - Dimensions: A4 bond paper - Format: PDF, created using LaTeX - **Answer Key** - Format: PDF, created using LaTeX - **Table of Specifications** - XLSX format --- Salamat sa pagsuporta sa **TeXMathPro, KasaMath**! Kung may tanong o suggestion ka, [kontakin mo lang ako](mailto:texmathpro@gmail.com). | F33: 79 | G33: 69 | H33: FALSE | I33: 46176 | J33: TRUE | K33: 46179 | L33: --- 📑 **Competencies Covered** - Determine the measures of angles of polygons. - Determine the number of sides of polygons. - Solve problems involving percentage increase and percentage decrease. - Solve money problems involving percentages (e. g., discount, commission, sales tax, simple interest). - Create a financial plan. | M33: {=_xlfn.XLOOKUP(TRUE,ISNUMBER(SEARCH(Sheet2!A$23:A$26,A33)),Sheet2!B$23:B$26,"")} -> Second Summative test | N33: {=_xlfn.XLOOKUP(TRUE,ISNUMBER(SEARCH(Sheet2!A$32:A$34,A33)),Sheet2!B$32:B$34,"")} -> First Term | O33: {=_xlfn.XLOOKUP(TRUE,ISNUMBER(SEARCH(Sheet2!A$38:A$41,A33)),Sheet2!B$38:B$41,"")} -> Grade 7 | P33: {=_xlfn.XLOOKUP(TRUE,ISNUMBER(SEARCH(Sheet2!A$45:A$47,A33)),Sheet2!B$45:B$47,"")} -> Standard Assessment Package | Q33: 15 | R33: 25
A34: G7-T1-S2-CP | B34: Grade 7 T1 Second Summative Test + Answer Key + TOS (Custom) | C34: https://res.cloudinary.com/dadubemrv/image/upload/v1784692768/blzn2f4qf4csagllrdmj.png,https://res.cloudinary.com/dadubemrv/image/upload/v1784692772/mlwmihwoocbpcd5of6rx.png,https://res.cloudinary.com/dadubemrv/image/upload/v1784692776/adpmufdqkz5qxw5yzj0p.png | D34: =CONCATENATE("*Tinatamad ka ba, walang time, o nahihirapang gumawa ng TOS at ", Sheet1!M34, " mo, ",Sheet1!O34," KasaMath? Kuha ka na ng ", Sheet1!P34,"!* **Bakit perfect para sa’yo ang ", Sheet1!P34,"?** ",Sheet2!F$17," - Perfect sa teachers na gusto ng pasadyang exam", _xlfn._LONGTEXT(" [![Sample TOS formatted using 21st Century Skills](https://res.cloudinary.com/dadubemrv/image/upload/v1768351176/tv5zwilsnzrad6r2q6sw.png)](https://res.cloudinary.com/dadubemrv/image/upload/v1768351176/tv5zwilsnzrad6r2q6sw.png) *Sample TOS formatted us","ing 21st Century Skills*"),L34, " --- ## Step 1: I-fill out at i-submit ang Order Form. ", "{{< iframe src=""", "https://cityofsmiles.github.io/auto-order-form/?id=", LOWER(A34), """ height=""850"" >}}"," ## Step 2: Payment and Delivery ### Payment Methods Mag-send ka lang ng ₱",Sheet1!F34," para sa **", Sheet1!M34,_xlfn._LONGTEXT("**. - **Landbank**: 0695077289 (Jonathan R. Bacolod) - **GCash**: 09128389571 (Jonathan Bacolod) - **Maya**: 09128389571 (Jonathan Bacolod) **Isend ang Screenshot ng Payment kahit saan dito:** - Email: [texmathpro@gmail.com](mailto:texmathpro@gm","ail.com) - Facebook: https://m.me/jonathan.r.bacolod - Telegram: https://t.me/Jonathan_Bacolod Isesend ko ang files sa email address mo after ng payment. ### Delivery Includes: - **Test** - Test type: "), Sheet1!R34,"-item multiple choice test - Dimensions: A4 bond paper - Format: PDF, created using LaTeX - **Answer Key** - Format: PDF, created using LaTeX - **Table of Specifications** - XLSX format", Sheet2!$D$6) -> *Tinatamad ka ba, walang time, o nahihirapang gumawa ng TOS at Second Summative test mo, Grade 7 KasaMath? Kuha ka na ng Custom Assessment Package!* **Bakit perfect para sa’yo ang Custom Assessment Package?** - Makakatipid ka sa oras kaya makakapaghabol pa ng lessons. - Maganda at consistent ang formatting ng test questions at figures. - Ready na ang answer key kaya mas madali at mabilis ang pagche-check. - Fully customizable exam: kahit anong topic ang pwedeng covered - Maaga kang makakapag-submit ng TOS sa head mo. - Table of Specifications using the 21st Century format - Number of days: pwede kahit ilan - Number of items: kahit ilan basta maximum of 50 - Perfect sa teachers na gusto ng pasadyang exam [![Sample TOS formatted using 21st Century Skills](https://res.cloudinary.com/dadubemrv/image/upload/v1768351176/tv5zwilsnzrad6r2q6sw.png)](https://res.cloudinary.com/dadubemrv/image/upload/v1768351176/tv5zwilsnzrad6r2q6sw.png) *Sample TOS formatted using 21st Century Skills* --- 📑 **Competencies Covered** - Determine the measures of angles of polygons. - Determine the number of sides of polygons. - Solve problems involving percentage increase and percentage decrease. - Solve money problems involving percentages (e. g., discount, commission, sales tax, simple interest). - Create a financial plan. --- ## Step 1: I-fill out at i-submit ang Order Form. {{< iframe src="https://cityofsmiles.github.io/auto-order-form/?id=g7-t1-s2-cp" height="850" >}} ## Step 2: Payment and Delivery ### Payment Methods Mag-send ka lang ng ₱179 para sa **Second Summative test**. - **Landbank**: 0695077289 (Jonathan R. Bacolod) - **GCash**: 09128389571 (Jonathan Bacolod) - **Maya**: 09128389571 (Jonathan Bacolod) **Isend ang Screenshot ng Payment kahit saan dito:** - Email: [texmathpro@gmail.com](mailto:texmathpro@gmail.com) - Facebook: https://m.me/jonathan.r.bacolod - Telegram: https://t.me/Jonathan_Bacolod Isesend ko ang files sa email address mo after ng payment. ### Delivery Includes: - **Test** - Test type: 25-50-item multiple choice test - Dimensions: A4 bond paper - Format: PDF, created using LaTeX - **Answer Key** - Format: PDF, created using LaTeX - **Table of Specifications** - XLSX format --- Salamat sa pagsuporta sa **TeXMathPro, KasaMath**! Kung may tanong o suggestion ka, [kontakin mo lang ako](mailto:texmathpro@gmail.com). | F34: 179 | G34: 169 | H34: FALSE | I34: 46176 | J34: TRUE | K34: 46179 | L34: --- 📑 **Competencies Covered** - Determine the measures of angles of polygons. - Determine the number of sides of polygons. - Solve problems involving percentage increase and percentage decrease. - Solve money problems involving percentages (e. g., discount, commission, sales tax, simple interest). - Create a financial plan. | M34: {=_xlfn.XLOOKUP(TRUE,ISNUMBER(SEARCH(Sheet2!A$23:A$26,A34)),Sheet2!B$23:B$26,"")} -> Second Summative test | N34: {=_xlfn.XLOOKUP(TRUE,ISNUMBER(SEARCH(Sheet2!A$32:A$34,A34)),Sheet2!B$32:B$34,"")} -> First Term | O34: {=_xlfn.XLOOKUP(TRUE,ISNUMBER(SEARCH(Sheet2!A$38:A$41,A34)),Sheet2!B$38:B$41,"")} -> Grade 7 | P34: {=_xlfn.XLOOKUP(TRUE,ISNUMBER(SEARCH(Sheet2!A$45:A$47,A34)),Sheet2!B$45:B$47,"")} -> Custom Assessment Package | R34: 25-50
A35: G8-T1-S1-BP | B35: Grade 8 T1 First Summative Test + TOS + Answer Key (Basic) | C35: https://i.imgur.com/dqV0sYm.jpeg | D35: =Sheet2!$D$2 -> 0 | F35: 120 | G35: 84 | H35: FALSE | I35: 46176 | J35: FALSE | K35: 46176
A36: G8-T1-S1-SP | B36: Grade 8 T1 First Summative Test + TOS + Answer Key (Standard) | C36: https://i.imgur.com/dqV0sYm.jpeg | D36: =Sheet2!$E$2 -> 0 | F36: 165 | G36: 115 | H36: FALSE | I36: 46176 | J36: FALSE | K36: 46176
A37: G8-T1-S1-CP | B37: Grade 8 T1 First Summative Test + TOS + Answer Key (Custom) | C37: https://i.imgur.com/dqV0sYm.jpeg | D37: =Sheet2!$F$2 -> 0 | F37: 350 | G37: 245 | H37: FALSE | I37: 46176 | J37: FALSE | K37: 46176
A38: G9-T1-S1-BP | B38: Grade 9 T1 First Summative Test + Answer Key (Basic) | C38: https://res.cloudinary.com/dadubemrv/image/upload/v1783263602/yd7hsdwqb5dk19s6pakw.png,https://res.cloudinary.com/dadubemrv/image/upload/v1783263605/ujoydnhzuhsnv7yic56j.png,https://res.cloudinary.com/dadubemrv/image/upload/v1783263608/d8tvcndvdvbcscplmsni.png,https://res.cloudinary.com/dadubemrv/image/upload/v1783263611/xnrnsjt720lvbgoycchm.png | D38: =CONCATENATE("*Tinatamad ka ba, walang time, o nahihirapang gumawa ng TOS at ", Sheet1!M38, " mo, ",Sheet1!O38," KasaMath? Kuha ka na ng ", Sheet1!P38,"!* **Bakit perfect para sa’yo ang ", Sheet1!P38,"?** ",Sheet2!D$17, Sheet1!Q38," days - ", Sheet1!R38,"-item Multiple Choice test with Answer Key - Para sa teachers na nagmamadali at hindi kailangan ang TOS", L38, " --- ## Step 1: I-fill out at i-submit ang Order Form. ", "{{< iframe src=""", "https://cityofsmiles.github.io/auto-order-form/?id=", LOWER(A38), """ height=""850"" >}}"," ## Step 2: Payment and Delivery ### Payment Methods Mag-send ka lang ng ₱",Sheet1!F38," para sa **", Sheet1!M38,_xlfn._LONGTEXT("**. - **Landbank**: 0695077289 (Jonathan R. Bacolod) - **GCash**: 09128389571 (Jonathan Bacolod) - **Maya**: 09128389571 (Jonathan Bacolod) **Isend ang Screenshot ng Payment kahit saan dito:** - Email: [texmathpro@gmail.com](mailto:texmathpro@gm","ail.com) - Facebook: https://m.me/jonathan.r.bacolod - Telegram: https://t.me/Jonathan_Bacolod Isesend ko ang files sa email address mo after ng payment. ### Delivery Includes: - **Test** - Test type: "), Sheet1!R38,"-item multiple choice test - Dimensions: A4 bond paper - Format: PDF, created using LaTeX - **Answer Key** - Format: PDF, created using LaTeX", Sheet2!$D$6) -> *Tinatamad ka ba, walang time, o nahihirapang gumawa ng TOS at First Summative test mo, Grade 9 KasaMath? Kuha ka na ng Basic Assessment Package!* **Bakit perfect para sa’yo ang Basic Assessment Package?** - Makakatipid ka sa oras kaya makakapaghabol pa ng lessons. - Maganda at consistent ang formatting ng test questions at figures. - Ready na ang answer key kaya mas madali at mabilis ang pagche-check. - Ready-to-print exam: sakto sa Budget of Work ang covered topics - Number of days: 15 days - 25-item Multiple Choice test with Answer Key - Para sa teachers na nagmamadali at hindi kailangan ang TOS --- 📑 **Competencies Covered** - Illustrate and describe point, line, ray, line segment, angle, and plane using models and geometric notations. - Construct perpendicular and parallel lines. - Identify the relationships between angles formed by parallel lines cut by a transversal. - Determine angle measures involving angle pairs, parallel and perpendicular lines, and parallel lines cut by a transversal. - Identify relations that are functions based on the definitions of relations and functions. - Determine the domain and range of a function expressed in different representations. --- ## Step 1: I-fill out at i-submit ang Order Form. {{< iframe src="https://cityofsmiles.github.io/auto-order-form/?id=g9-t1-s1-bp" height="850" >}} ## Step 2: Payment and Delivery ### Payment Methods Mag-send ka lang ng ₱59 para sa **First Summative test**. - **Landbank**: 0695077289 (Jonathan R. Bacolod) - **GCash**: 09128389571 (Jonathan Bacolod) - **Maya**: 09128389571 (Jonathan Bacolod) **Isend ang Screenshot ng Payment kahit saan dito:** - Email: [texmathpro@gmail.com](mailto:texmathpro@gmail.com) - Facebook: https://m.me/jonathan.r.bacolod - Telegram: https://t.me/Jonathan_Bacolod Isesend ko ang files sa email address mo after ng payment. ### Delivery Includes: - **Test** - Test type: 25-item multiple choice test - Dimensions: A4 bond paper - Format: PDF, created using LaTeX - **Answer Key** - Format: PDF, created using LaTeX --- Salamat sa pagsuporta sa **TeXMathPro, KasaMath**! Kung may tanong o suggestion ka, [kontakin mo lang ako](mailto:texmathpro@gmail.com). | F38: 59 | G38: 49 | H38: FALSE | I38: 46176 | J38: TRUE | K38: 46179 | L38: --- 📑 **Competencies Covered** - Illustrate and describe point, line, ray, line segment, angle, and plane using models and geometric notations. - Construct perpendicular and parallel lines. - Identify the relationships between angles formed by parallel lines cut by a transversal. - Determine angle measures involving angle pairs, parallel and perpendicular lines, and parallel lines cut by a transversal. - Identify relations that are functions based on the definitions of relations and functions. - Determine the domain and range of a function expressed in different representations. | M38: {=_xlfn.XLOOKUP(TRUE,ISNUMBER(SEARCH(Sheet2!A$23:A$26,A38)),Sheet2!B$23:B$26,"")} -> First Summative test | N38: {=_xlfn.XLOOKUP(TRUE,ISNUMBER(SEARCH(Sheet2!A$32:A$34,A38)),Sheet2!B$32:B$34,"")} -> First Term | O38: {=_xlfn.XLOOKUP(TRUE,ISNUMBER(SEARCH(Sheet2!A$38:A$41,A38)),Sheet2!B$38:B$41,"")} -> Grade 9 | P38: {=_xlfn.XLOOKUP(TRUE,ISNUMBER(SEARCH(Sheet2!A$45:A$47,A38)),Sheet2!B$45:B$47,"")} -> Basic Assessment Package | Q38: 15 | R38: 25
A39: G9-T1-S1-SP | B39: Grade 9 T1 First Summative Test + Answer Key + TOS (Standard) | C39: https://res.cloudinary.com/dadubemrv/image/upload/v1783263602/yd7hsdwqb5dk19s6pakw.png,https://res.cloudinary.com/dadubemrv/image/upload/v1783263605/ujoydnhzuhsnv7yic56j.png,https://res.cloudinary.com/dadubemrv/image/upload/v1783263608/d8tvcndvdvbcscplmsni.png,https://res.cloudinary.com/dadubemrv/image/upload/v1783263611/xnrnsjt720lvbgoycchm.png | D39: =CONCATENATE("*Tinatamad ka ba, walang time, o nahihirapang gumawa ng TOS at ", Sheet1!M39, " mo, ",Sheet1!O39," KasaMath? Kuha ka na ng ", Sheet1!P39,"!* **Bakit perfect para sa’yo ang ", Sheet1!P39,"?** ",Sheet2!E$17, Sheet1!Q39," days - ", Sheet1!R39,"-item Multiple Choice test with Answer Key - Bagay sa teachers na gusto ng kumpletong exam, answer key, at TOS", _xlfn._LONGTEXT(" [![Sample TOS formatted using 21st Century Skills](https://res.cloudinary.com/dadubemrv/image/upload/v1768351176/tv5zwilsnzrad6r2q6sw.png)](https://res.cloudinary.com/dadubemrv/image/upload/v1768351176/tv5zwilsnzrad6r2q6sw.png) *Sample TOS formatted us","ing 21st Century Skills*"),L39, " --- ## Step 1: I-fill out at i-submit ang Order Form. ", "{{< iframe src=""", "https://cityofsmiles.github.io/auto-order-form/?id=", LOWER(A39), """ height=""850"" >}}"," ## Step 2: Payment and Delivery ### Payment Methods Mag-send ka lang ng ₱",Sheet1!F39," para sa **", Sheet1!M39,_xlfn._LONGTEXT("**. - **Landbank**: 0695077289 (Jonathan R. Bacolod) - **GCash**: 09128389571 (Jonathan Bacolod) - **Maya**: 09128389571 (Jonathan Bacolod) **Isend ang Screenshot ng Payment kahit saan dito:** - Email: [texmathpro@gmail.com](mailto:texmathpro@gm","ail.com) - Facebook: https://m.me/jonathan.r.bacolod - Telegram: https://t.me/Jonathan_Bacolod Isesend ko ang files sa email address mo after ng payment. ### Delivery Includes: - **Test** - Test type: "), Sheet1!R39,"-item multiple choice test - Dimensions: A4 bond paper - Format: PDF, created using LaTeX - **Answer Key** - Format: PDF, created using LaTeX - **Table of Specifications** - XLSX format", Sheet2!$D$6) -> *Tinatamad ka ba, walang time, o nahihirapang gumawa ng TOS at First Summative test mo, Grade 9 KasaMath? Kuha ka na ng Standard Assessment Package!* **Bakit perfect para sa’yo ang Standard Assessment Package?** - Makakatipid ka sa oras kaya makakapaghabol pa ng lessons. - Maganda at consistent ang formatting ng test questions at figures. - Ready na ang answer key kaya mas madali at mabilis ang pagche-check. - Ready-to-print exam: sakto sa Budget of Work ang covered topics - Maaga kang makakapag-submit ng TOS sa head mo. - Table of Specifications using the 21st Century format - Number of days: 15 days - 25-item Multiple Choice test with Answer Key - Bagay sa teachers na gusto ng kumpletong exam, answer key, at TOS [![Sample TOS formatted using 21st Century Skills](https://res.cloudinary.com/dadubemrv/image/upload/v1768351176/tv5zwilsnzrad6r2q6sw.png)](https://res.cloudinary.com/dadubemrv/image/upload/v1768351176/tv5zwilsnzrad6r2q6sw.png) *Sample TOS formatted using 21st Century Skills* --- 📑 **Competencies Covered** - Illustrate and describe point, line, ray, line segment, angle, and plane using models and geometric notations. - Construct perpendicular and parallel lines. - Identify the relationships between angles formed by parallel lines cut by a transversal. - Determine angle measures involving angle pairs, parallel and perpendicular lines, and parallel lines cut by a transversal. - Identify relations that are functions based on the definitions of relations and functions. - Determine the domain and range of a function expressed in different representations. --- ## Step 1: I-fill out at i-submit ang Order Form. {{< iframe src="https://cityofsmiles.github.io/auto-order-form/?id=g9-t1-s1-sp" height="850" >}} ## Step 2: Payment and Delivery ### Payment Methods Mag-send ka lang ng ₱79 para sa **First Summative test**. - **Landbank**: 0695077289 (Jonathan R. Bacolod) - **GCash**: 09128389571 (Jonathan Bacolod) - **Maya**: 09128389571 (Jonathan Bacolod) **Isend ang Screenshot ng Payment kahit saan dito:** - Email: [texmathpro@gmail.com](mailto:texmathpro@gmail.com) - Facebook: https://m.me/jonathan.r.bacolod - Telegram: https://t.me/Jonathan_Bacolod Isesend ko ang files sa email address mo after ng payment. ### Delivery Includes: - **Test** - Test type: 25-item multiple choice test - Dimensions: A4 bond paper - Format: PDF, created using LaTeX - **Answer Key** - Format: PDF, created using LaTeX - **Table of Specifications** - XLSX format --- Salamat sa pagsuporta sa **TeXMathPro, KasaMath**! Kung may tanong o suggestion ka, [kontakin mo lang ako](mailto:texmathpro@gmail.com). | F39: 79 | G39: 69 | H39: FALSE | I39: 46176 | J39: TRUE | K39: 46179 | L39: --- 📑 **Competencies Covered** - Illustrate and describe point, line, ray, line segment, angle, and plane using models and geometric notations. - Construct perpendicular and parallel lines. - Identify the relationships between angles formed by parallel lines cut by a transversal. - Determine angle measures involving angle pairs, parallel and perpendicular lines, and parallel lines cut by a transversal. - Identify relations that are functions based on the definitions of relations and functions. - Determine the domain and range of a function expressed in different representations. | M39: {=_xlfn.XLOOKUP(TRUE,ISNUMBER(SEARCH(Sheet2!A$23:A$26,A39)),Sheet2!B$23:B$26,"")} -> First Summative test | N39: {=_xlfn.XLOOKUP(TRUE,ISNUMBER(SEARCH(Sheet2!A$32:A$34,A39)),Sheet2!B$32:B$34,"")} -> First Term | O39: {=_xlfn.XLOOKUP(TRUE,ISNUMBER(SEARCH(Sheet2!A$38:A$41,A39)),Sheet2!B$38:B$41,"")} -> Grade 9 | P39: {=_xlfn.XLOOKUP(TRUE,ISNUMBER(SEARCH(Sheet2!A$45:A$47,A39)),Sheet2!B$45:B$47,"")} -> Standard Assessment Package | Q39: 15 | R39: 25
A40: G9-T1-S1-CP | B40: Grade 9 T1 First Summative Test + Answer Key + TOS (Custom) | C40: https://res.cloudinary.com/dadubemrv/image/upload/v1783263602/yd7hsdwqb5dk19s6pakw.png,https://res.cloudinary.com/dadubemrv/image/upload/v1783263605/ujoydnhzuhsnv7yic56j.png,https://res.cloudinary.com/dadubemrv/image/upload/v1783263608/d8tvcndvdvbcscplmsni.png,https://res.cloudinary.com/dadubemrv/image/upload/v1783263611/xnrnsjt720lvbgoycchm.png | D40: =CONCATENATE("*Tinatamad ka ba, walang time, o nahihirapang gumawa ng TOS at ", Sheet1!M40, " mo, ",Sheet1!O40," KasaMath? Kuha ka na ng ", Sheet1!P40,"!* **Bakit perfect para sa’yo ang ", Sheet1!P40,"?** ",Sheet2!F$17," - Perfect sa teachers na gusto ng pasadyang exam", _xlfn._LONGTEXT(" [![Sample TOS formatted using 21st Century Skills](https://res.cloudinary.com/dadubemrv/image/upload/v1768351176/tv5zwilsnzrad6r2q6sw.png)](https://res.cloudinary.com/dadubemrv/image/upload/v1768351176/tv5zwilsnzrad6r2q6sw.png) *Sample TOS formatted us","ing 21st Century Skills*"),L40, " --- ## Step 1: I-fill out at i-submit ang Order Form. ", "{{< iframe src=""", "https://cityofsmiles.github.io/auto-order-form/?id=", LOWER(A40), """ height=""850"" >}}"," ## Step 2: Payment and Delivery ### Payment Methods Mag-send ka lang ng ₱",Sheet1!F40," para sa **", Sheet1!M40,_xlfn._LONGTEXT("**. - **Landbank**: 0695077289 (Jonathan R. Bacolod) - **GCash**: 09128389571 (Jonathan Bacolod) - **Maya**: 09128389571 (Jonathan Bacolod) **Isend ang Screenshot ng Payment kahit saan dito:** - Email: [texmathpro@gmail.com](mailto:texmathpro@gm","ail.com) - Facebook: https://m.me/jonathan.r.bacolod - Telegram: https://t.me/Jonathan_Bacolod Isesend ko ang files sa email address mo after ng payment. ### Delivery Includes: - **Test** - Test type: "), Sheet1!R40,"-item multiple choice test - Dimensions: A4 bond paper - Format: PDF, created using LaTeX - **Answer Key** - Format: PDF, created using LaTeX - **Table of Specifications** - XLSX format", Sheet2!$D$6) -> *Tinatamad ka ba, walang time, o nahihirapang gumawa ng TOS at First Summative test mo, Grade 9 KasaMath? Kuha ka na ng Custom Assessment Package!* **Bakit perfect para sa’yo ang Custom Assessment Package?** - Makakatipid ka sa oras kaya makakapaghabol pa ng lessons. - Maganda at consistent ang formatting ng test questions at figures. - Ready na ang answer key kaya mas madali at mabilis ang pagche-check. - Fully customizable exam: kahit anong topic ang pwedeng covered - Maaga kang makakapag-submit ng TOS sa head mo. - Table of Specifications using the 21st Century format - Number of days: pwede kahit ilan - Number of items: kahit ilan basta maximum of 50 - Perfect sa teachers na gusto ng pasadyang exam [![Sample TOS formatted using 21st Century Skills](https://res.cloudinary.com/dadubemrv/image/upload/v1768351176/tv5zwilsnzrad6r2q6sw.png)](https://res.cloudinary.com/dadubemrv/image/upload/v1768351176/tv5zwilsnzrad6r2q6sw.png) *Sample TOS formatted using 21st Century Skills* --- 📑 **Competencies Covered** - Illustrate and describe point, line, ray, line segment, angle, and plane using models and geometric notations. - Construct perpendicular and parallel lines. - Identify the relationships between angles formed by parallel lines cut by a transversal. - Determine angle measures involving angle pairs, parallel and perpendicular lines, and parallel lines cut by a transversal. - Identify relations that are functions based on the definitions of relations and functions. - Determine the domain and range of a function expressed in different representations. --- ## Step 1: I-fill out at i-submit ang Order Form. {{< iframe src="https://cityofsmiles.github.io/auto-order-form/?id=g9-t1-s1-cp" height="850" >}} ## Step 2: Payment and Delivery ### Payment Methods Mag-send ka lang ng ₱179 para sa **First Summative test**. - **Landbank**: 0695077289 (Jonathan R. Bacolod) - **GCash**: 09128389571 (Jonathan Bacolod) - **Maya**: 09128389571 (Jonathan Bacolod) **Isend ang Screenshot ng Payment kahit saan dito:** - Email: [texmathpro@gmail.com](mailto:texmathpro@gmail.com) - Facebook: https://m.me/jonathan.r.bacolod - Telegram: https://t.me/Jonathan_Bacolod Isesend ko ang files sa email address mo after ng payment. ### Delivery Includes: - **Test** - Test type: 25-50-item multiple choice test - Dimensions: A4 bond paper - Format: PDF, created using LaTeX - **Answer Key** - Format: PDF, created using LaTeX - **Table of Specifications** - XLSX format --- Salamat sa pagsuporta sa **TeXMathPro, KasaMath**! Kung may tanong o suggestion ka, [kontakin mo lang ako](mailto:texmathpro@gmail.com). | F40: 179 | G40: 169 | H40: FALSE | I40: 46176 | J40: TRUE | K40: 46179 | L40: --- 📑 **Competencies Covered** - Illustrate and describe point, line, ray, line segment, angle, and plane using models and geometric notations. - Construct perpendicular and parallel lines. - Identify the relationships between angles formed by parallel lines cut by a transversal. - Determine angle measures involving angle pairs, parallel and perpendicular lines, and parallel lines cut by a transversal. - Identify relations that are functions based on the definitions of relations and functions. - Determine the domain and range of a function expressed in different representations. | M40: {=_xlfn.XLOOKUP(TRUE,ISNUMBER(SEARCH(Sheet2!A$23:A$26,A40)),Sheet2!B$23:B$26,"")} -> First Summative test | N40: {=_xlfn.XLOOKUP(TRUE,ISNUMBER(SEARCH(Sheet2!A$32:A$34,A40)),Sheet2!B$32:B$34,"")} -> First Term | O40: {=_xlfn.XLOOKUP(TRUE,ISNUMBER(SEARCH(Sheet2!A$38:A$41,A40)),Sheet2!B$38:B$41,"")} -> Grade 9 | P40: {=_xlfn.XLOOKUP(TRUE,ISNUMBER(SEARCH(Sheet2!A$45:A$47,A40)),Sheet2!B$45:B$47,"")} -> Custom Assessment Package | R40: 25-50
